Workbook

Sheet Tổng hợp
A1: Bộ test case – Saucedemo (Đăng nhập, Giỏ hàng, Thanh toán)
A2: Website: https://www.saucedemo.com · Mật khẩu chung: secret_sauce
A4: Theo chức năng
A5: Chức năng | B5: Positive | C5: Negative | D5: Tổng | E5: Pass | F5: Fail
A6: Đăng nhập | B6: =COUNTIFS('Test cases'!$B:$B,$A6,'Test cases'!$C:$C,"Positive") -> 5 | C6: =COUNTIFS('Test cases'!$B:$B,$A6,'Test cases'!$C:$C,"Negative") -> 10 | D6: =B6+C6 -> 15 | E6: =COUNTIFS('Test cases'!$B:$B,$A6,'Test cases'!$L:$L,"Pass") -> 0 | F6: =COUNTIFS('Test cases'!$B:$B,$A6,'Test cases'!$L:$L,"Fail") -> 0
A7: Danh sách sản phẩm | B7: =COUNTIFS('Test cases'!$B:$B,$A7,'Test cases'!$C:$C,"Positive") -> 4 | C7: =COUNTIFS('Test cases'!$B:$B,$A7,'Test cases'!$C:$C,"Negative") -> 0 | D7: =B7+C7 -> 4 | E7: =COUNTIFS('Test cases'!$B:$B,$A7,'Test cases'!$L:$L,"Pass") -> 0 | F7: =COUNTIFS('Test cases'!$B:$B,$A7,'Test cases'!$L:$L,"Fail") -> 0
A8: Giỏ hàng | B8: =COUNTIFS('Test cases'!$B:$B,$A8,'Test cases'!$C:$C,"Positive") -> 11 | C8: =COUNTIFS('Test cases'!$B:$B,$A8,'Test cases'!$C:$C,"Negative") -> 2 | D8: =B8+C8 -> 13 | E8: =COUNTIFS('Test cases'!$B:$B,$A8,'Test cases'!$L:$L,"Pass") -> 0 | F8: =COUNTIFS('Test cases'!$B:$B,$A8,'Test cases'!$L:$L,"Fail") -> 0
A9: Thanh toán | B9: =COUNTIFS('Test cases'!$B:$B,$A9,'Test cases'!$C:$C,"Positive") -> 9 | C9: =COUNTIFS('Test cases'!$B:$B,$A9,'Test cases'!$C:$C,"Negative") -> 9 | D9: =B9+C9 -> 18 | E9: =COUNTIFS('Test cases'!$B:$B,$A9,'Test cases'!$L:$L,"Pass") -> 0 | F9: =COUNTIFS('Test cases'!$B:$B,$A9,'Test cases'!$L:$L,"Fail") -> 0
A10: Tổng | B10: =SUM(B6:B9) -> 29 | C10: =SUM(C6:C9) -> 21 | D10: =SUM(D6:D9) -> 50 | E10: =SUM(E6:E9) -> 0 | F10: =SUM(F6:F9) -> 0
A12: Theo trạng thái automation
A13: Đã có | B13: =COUNTIF('Test cases'!$J:$J,$A13) -> 38
A14: Cần viết | B14: =COUNTIF('Test cases'!$J:$J,$A14) -> 3
A15: Test tay | B15: =COUNTIF('Test cases'!$J:$J,$A15) -> 9
A17: Theo kết quả chạy
A18: Not run | B18: =COUNTIF('Test cases'!$L:$L,$A18) -> 50
A19: Pass | B19: =COUNTIF('Test cases'!$L:$L,$A19) -> 0
A20: Fail | B20: =COUNTIF('Test cases'!$L:$L,$A20) -> 0
A21: Blocked | B21: =COUNTIF('Test cases'!$L:$L,$A21) -> 0
A23: Hướng dẫn
A24: • Ô nền vàng (cột Kết quả thực tế, Trạng thái) là chỗ bạn điền khi chạy test. Trạng thái chọn từ danh sách: Not run / Pass / Fail / Blocked.
A25: • Ví dụ điền: Kết quả thực tế = "Hiển thị đúng lỗi Username is required", Trạng thái = Pass.
A26: • Automation: "Đã có" = đã có code trong project (cột cuối ghi tên hàm test tương ứng); "Cần viết" = nên viết thêm code; "Test tay" = chạy tay trước để xác nhận hành vi.
A27: • Case ghi chú "dự kiến FAIL" dùng các user Saucedemo cố ý cài lỗi (problem_user, error_user) hoặc trang thiếu kiểm tra. Đây là các case để luyện log bug.
A28: • Các tài khoản: standard_user, locked_out_user, problem_user, performance_glitch_user, error_user, visual_user.

Sheet Test cases
A1: ID | B1: Chức năng | C1: Loại case | D1: Tiêu đề | E1: Điều kiện trước | F1: Các bước | G1: Dữ liệu test | H1: Kết quả mong đợi | I1: Độ ưu tiên | J1: Automation | K1: Kết quả thực tế | L1: Trạng thái | M1: Ghi chú | N1: Hàm test tự động
A2: TC_LG_01 | B2: Đăng nhập | C2: Positive | D2: Đăng nhập thành công với tài khoản hợp lệ | E2: Mở trang https://www.saucedemo.com | F2: 1. Nhập Username 2. Nhập Password 3. Bấm Login | G2: standard_user / secret_sauce | H2: Chuyển sang trang /inventory.html, tiêu đề "Products", hiển thị 6 sản phẩm | I2: High | J2: Đã có | L2: Not run | N2: test_login_success
A3: TC_LG_02 | B3: Đăng nhập | C3: Positive | D3: Đăng nhập bằng phím Enter | E3: Mở trang https://www.saucedemo.com | F3: 1. Nhập Username, Password 2. Nhấn Enter tại ô Password | G3: standard_user / secret_sauce | H3: Đăng nhập thành công, chuyển sang trang Products | I3: Medium | J3: Đã có | L3: Not run | N3: test_login_with_enter_key
A4: TC_LG_03 | B4: Đăng nhập | C4: Positive | D4: Mật khẩu hiển thị dạng ẩn | E4: Mở trang https://www.saucedemo.com | F4: 1. Nhập Password | G4: secret_sauce | H4: Ký tự mật khẩu hiển thị dạng ẩn (•••), ô có type=password | I4: Medium | J4: Đã có | L4: Not run | N4: test_password_is_masked
A5: TC_LG_04 | B5: Đăng nhập | C5: Negative | D5: Bỏ trống cả Username và Password | E5: Mở trang https://www.saucedemo.com | F5: 1. Để trống 2 ô 2. Bấm Login | G5: (trống) | H5: Hiển thị lỗi "Epic sadface: Username is required", vẫn ở trang đăng nhập | I5: High | J5: Đã có | L5: Not run | N5: test_login_negative[both_empty]
A6: TC_LG_05 | B6: Đăng nhập | C6: Negative | D6: Bỏ trống Username | E6: Mở trang https://www.saucedemo.com | F6: 1. Để trống Username 2. Nhập Password 3. Bấm Login | G6: Password: secret_sauce | H6: Hiển thị lỗi "Epic sadface: Username is required" | I6: High | J6: Đã có | L6: Not run | N6: test_login_negative[empty_username]
A7: TC_LG_06 | B7: Đăng nhập | C7: Negative | D7: Bỏ trống Password | E7: Mở trang https://www.saucedemo.com | F7: 1. Nhập Username 2. Để trống Password 3. Bấm Login | G7: Username: standard_user | H7: Hiển thị lỗi "Epic sadface: Password is required" | I7: High | J7: Đã có | L7: Not run | N7: test_login_negative[empty_password]
A8: TC_LG_07 | B8: Đăng nhập | C8: Negative | D8: Sai mật khẩu | E8: Mở trang https://www.saucedemo.com | F8: 1. Nhập Username đúng 2. Nhập Password sai 3. Bấm Login | G8: standard_user / wrong_password | H8: Hiển thị lỗi "Epic sadface: Username and password do not match any user in this service" | I8: High | J8: Đã có | L8: Not run | N8: test_login_negative[wrong_password]
A9: TC_LG_08 | B9: Đăng nhập | C9: Negative | D9: Username không tồn tại | E9: Mở trang https://www.saucedemo.com | F9: 1. Nhập Username không tồn tại 2. Nhập Password 3. Bấm Login | G9: abc_user / secret_sauce | H9: Hiển thị lỗi "...Username and password do not match any user in this service" | I9: Medium | J9: Đã có | L9: Not run | N9: test_login_negative[user_not_exist]
A10: TC_LG_09 | B10: Đăng nhập | C10: Negative | D10: Tài khoản bị khóa | E10: Mở trang https://www.saucedemo.com | F10: 1. Nhập user bị khóa 2. Bấm Login | G10: locked_out_user / secret_sauce | H10: Hiển thị lỗi "Epic sadface: Sorry, this user has been locked out." | I10: High | J10: Đã có | L10: Not run | N10: test_login_negative[locked_user]
A11: TC_LG_10 | B11: Đăng nhập | C11: Negative | D11: Username sai chữ hoa/thường | E11: Mở trang https://www.saucedemo.com | F11: 1. Nhập Username viết hoa 2. Nhập Password 3. Bấm Login | G11: Standard_User / secret_sauce | H11: Không đăng nhập được, hiển thị lỗi "...do not match..." | I11: Low | J11: Đã có | L11: Not run | N11: test_login_negative[wrong_case_username]
A12: TC_LG_11 | B12: Đăng nhập | C12: Negative | D12: Username có dấu cách ở đầu | E12: Mở trang https://www.saucedemo.com | F12: 1. Nhập Username có dấu cách đầu 2. Nhập Password 3. Bấm Login | G12: " standard_user" / secret_sauce | H12: Không đăng nhập được, hiển thị lỗi "...do not match..." | I12: Low | J12: Test tay | L12: Not run | M12: Cần chạy tay để xác nhận hành vi thực tế
A13: TC_LG_12 | B13: Đăng nhập | C13: Negative | D13: Truy cập thẳng trang sản phẩm khi chưa đăng nhập | E13: Chưa đăng nhập | F13: 1. Nhập URL https://www.saucedemo.com/inventory.html | H13: Ở lại trang đăng nhập, lỗi "Epic sadface: You can only access '/inventory.html' when you are logged in." | I13: High | J13: Đã có | L13: Not run | N13: test_open_inventory_without_login
A14: TC_LG_13 | B14: Đăng nhập | C14: Positive | D14: Đóng thông báo lỗi bằng nút X | E14: Đang hiển thị một thông báo lỗi đăng nhập | F14: 1. Bấm nút X trên thông báo lỗi | H14: Thông báo lỗi biến mất | I14: Low | J14: Đã có | L14: Not run | N14: test_close_error_message
A15: TC_LG_14 | B15: Đăng nhập | C15: Positive | D15: Đăng xuất | E15: Đã đăng nhập bằng standard_user | F15: 1. Bấm Menu (☰) 2. Bấm Logout | H15: Quay về trang đăng nhập, ô Username và Password trống | I15: High | J15: Đã có | L15: Not run | N15: test_logout
A16: TC_LG_15 | B16: Đăng nhập | C16: Negative | D16: Bấm Back trình duyệt sau khi đăng xuất | E16: Vừa đăng xuất | F16: 1. Bấm nút Back của trình duyệt | H16: Không vào được trang sản phẩm khi chưa đăng nhập lại | I16: Medium | J16: Test tay | L16: Not run | M16: Cần chạy tay để xác nhận hành vi thực tế
A17: TC_PL_01 | B17: Danh sách sản phẩm | C17: Positive | D17: Sắp xếp mặc định Name (A to Z) | E17: Đã đăng nhập bằng standard_user | F17: 1. Quan sát danh sách sản phẩm | H17: Sản phẩm sắp xếp theo tên A → Z | I17: Medium | J17: Cần viết | L17: Not run
A18: TC_PL_02 | B18: Danh sách sản phẩm | C18: Positive | D18: Sắp xếp Name (Z to A) | E18: Đã đăng nhập bằng standard_user | F18: 1. Chọn sắp xếp "Name (Z to A)" | H18: Sản phẩm sắp xếp theo tên Z → A | I18: Medium | J18: Cần viết | L18: Not run | M18: Code mẫu: test_sort_name_z_to_a
A19: TC_PL_03 | B19: Danh sách sản phẩm | C19: Positive | D19: Sắp xếp Price (low to high) | E19: Đã đăng nhập bằng standard_user | F19: 1. Chọn sắp xếp "Price (low to high)" | H19: Giá tăng dần | I19: Medium | J19: Đã có | L19: Not run | N19: test_sort_price_low_to_high
A20: TC_PL_04 | B20: Danh sách sản phẩm | C20: Positive | D20: Sắp xếp Price (high to low) | E20: Đã đăng nhập bằng standard_user | F20: 1. Chọn sắp xếp "Price (high to low)" | H20: Giá giảm dần | I20: Medium | J20: Cần viết | L20: Not run
A21: TC_CT_01 | B21: Giỏ hàng | C21: Positive | D21: Thêm 1 sản phẩm từ trang danh sách | E21: Đã đăng nhập bằng standard_user | F21: 1. Bấm "Add to cart" ở Sauce Labs Backpack | G21: Sauce Labs Backpack | H21: Nút đổi thành "Remove", icon giỏ hàng hiển thị 1 | I21: High | J21: Đã có | L21: Not run | N21: test_add_one_item
A22: TC_CT_02 | B22: Giỏ hàng | C22: Positive | D22: Thêm nhiều sản phẩm | E22: Đã đăng nhập bằng standard_user | F22: 1. Bấm "Add to cart" ở 3 sản phẩm | G22: Backpack, Bike Light, Bolt T-Shirt | H22: Icon giỏ hàng hiển thị 3 | I22: High | J22: Đã có | L22: Not run | N22: test_add_three_items
A23: TC_CT_03 | B23: Giỏ hàng | C23: Positive | D23: Thêm toàn bộ 6 sản phẩm | E23: Đã đăng nhập bằng standard_user | F23: 1. Bấm "Add to cart" ở cả 6 sản phẩm | G23: 6 sản phẩm | H23: Icon giỏ hàng hiển thị 6, tất cả nút đổi thành "Remove" | I23: Medium | J23: Đã có | L23: Not run | N23: test_add_all_items
A24: TC_CT_04 | B24: Giỏ hàng | C24: Positive | D24: Xóa sản phẩm ở trang danh sách | E24: Đã thêm 2 sản phẩm vào giỏ | F24: 1. Bấm "Remove" ở 1 sản phẩm | H24: Nút trở lại "Add to cart", icon giỏ hàng giảm từ 2 về 1 | I24: High | J24: Đã có | L24: Not run | N24: test_add_and_remove_item_updates_badge
A25: TC_CT_05 | B25: Giỏ hàng | C25: Positive | D25: Xóa hết sản phẩm thì icon giỏ không còn số | E25: Đã thêm 1 sản phẩm vào giỏ | F25: 1. Bấm "Remove" ở sản phẩm đó | H25: Số trên icon giỏ hàng biến mất (không hiển thị 0) | I25: Medium | J25: Đã có | L25: Not run | N25: test_badge_disappears_when_cart_empty
A26: TC_CT_06 | B26: Giỏ hàng | C26: Positive | D26: Thêm sản phẩm từ trang chi tiết | E26: Đã đăng nhập bằng standard_user | F26: 1. Bấm vào tên sản phẩm 2. Bấm "Add to cart" 3. Bấm "Back to products" | G26: Sauce Labs Backpack | H26: Icon giỏ hàng hiển thị 1; ở trang danh sách, nút của sản phẩm đó là "Remove" | I26: Medium | J26: Đã có | L26: Not run | N26: test_add_item_from_detail_page
A27: TC_CT_07 | B27: Giỏ hàng | C27: Positive | D27: Giỏ hàng hiển thị đúng thông tin sản phẩm | E27: Đã thêm Backpack ($29.99) vào giỏ | F27: 1. Bấm icon giỏ hàng | H27: Hiển thị đúng tên, giá $29.99, QTY = 1 | I27: High | J27: Đã có | L27: Not run | N27: test_cart_shows_correct_item
A28: TC_CT_08 | B28: Giỏ hàng | C28: Positive | D28: Xóa sản phẩm trong trang giỏ hàng | E28: Đã thêm 2 sản phẩm, đang ở trang giỏ hàng | F28: 1. Bấm "Remove" ở 1 sản phẩm | H28: Sản phẩm biến mất khỏi giỏ, icon giỏ hàng giảm còn 1 | I28: High | J28: Đã có | L28: Not run | N28: test_remove_item_in_cart_page
A29: TC_CT_09 | B29: Giỏ hàng | C29: Positive | D29: Continue Shopping giữ nguyên giỏ hàng | E29: Đã thêm 1 sản phẩm, đang ở trang giỏ hàng | F29: 1. Bấm "Continue Shopping" | H29: Quay về trang sản phẩm, icon giỏ hàng vẫn là 1 | I29: Medium | J29: Đã có | L29: Not run | N29: test_continue_shopping_keeps_cart
A30: TC_CT_10 | B30: Giỏ hàng | C30: Positive | D30: Giỏ hàng giữ nguyên sau khi tải lại trang | E30: Đã thêm 2 sản phẩm vào giỏ | F30: 1. Bấm F5 tải lại trang | H30: Icon giỏ hàng vẫn là 2 | I30: Medium | J30: Đã có | L30: Not run | N30: test_cart_kept_after_reload
A31: TC_CT_11 | B31: Giỏ hàng | C31: Positive | D31: Reset App State làm trống giỏ hàng | E31: Đã thêm 2 sản phẩm vào giỏ | F31: 1. Bấm Menu (☰) 2. Bấm "Reset App State" | H31: Icon giỏ hàng không còn số, giỏ hàng trống | I31: Low | J31: Đã có | L31: Not run | N31: test_reset_app_state_empties_cart
A32: TC_CT_12 | B32: Giỏ hàng | C32: Negative | D32: problem_user thêm sản phẩm vào giỏ | E32: Đăng nhập bằng problem_user | F32: 1. Bấm "Add to cart" ở cả 6 sản phẩm | G32: problem_user / secret_sauce | H32: Thêm được cả 6 sản phẩm, icon giỏ hàng hiển thị 6 | I32: Medium | J32: Test tay | L32: Not run | M32: Saucedemo cố ý cài lỗi cho user này. Dự kiến FAIL → log bug
A33: TC_CT_13 | B33: Giỏ hàng | C33: Negative | D33: error_user thêm/xóa sản phẩm | E33: Đăng nhập bằng error_user | F33: 1. Thêm rồi xóa từng sản phẩm | G33: error_user / secret_sauce | H33: Thêm/xóa hoạt động bình thường, không lỗi | I33: Medium | J33: Test tay | L33: Not run | M33: Saucedemo cố ý cài lỗi cho user này. Dự kiến FAIL → log bug
A34: TC_CO_01 | B34: Thanh toán | C34: Positive | D34: Đặt hàng thành công (E2E) | E34: Đã thêm 2 sản phẩm vào giỏ | F34: 1. Mở giỏ hàng, bấm Checkout 2. Nhập First Name, Last Name, Postal Code, bấm Continue 3. Bấm Finish | G34: Thuy / Ta / 100000 | H34: Hiển thị "Thank you for your order!", icon giỏ hàng không còn số | I34: High | J34: Đã có | L34: Not run | N34: test_checkout_total_is_correct
A35: TC_CO_02 | B35: Thanh toán | C35: Positive | D35: Bấm Checkout chuyển sang bước nhập thông tin | E35: Đã thêm 1 sản phẩm, đang ở trang giỏ hàng | F35: 1. Bấm Checkout | H35: Chuyển sang trang "Checkout: Your Information" có 3 ô nhập | I35: High | J35: Đã có | L35: Not run | N35: test_checkout_opens_information_page
A36: TC_CO_03 | B36: Thanh toán | C36: Negative | D36: Bỏ trống First Name | E36: Đang ở bước "Checkout: Your Information" | F36: 1. Để trống First Name 2. Nhập Last Name, Postal Code 3. Bấm Continue | G36: (trống) / Ta / 100000 | H36: Hiển thị lỗi "Error: First Name is required", không sang bước sau | I36: High | J36: Đã có | L36: Not run | N36: test_checkout_required_fields[empty_first_name]
A37: TC_CO_04 | B37: Thanh toán | C37: Negative | D37: Bỏ trống Last Name | E37: Đang ở bước "Checkout: Your Information" | F37: 1. Nhập First Name 2. Để trống Last Name 3. Nhập Postal Code 4. Bấm Continue | G37: Thuy / (trống) / 100000 | H37: Hiển thị lỗi "Error: Last Name is required" | I37: High | J37: Đã có | L37: Not run | N37: test_checkout_required_fields[empty_last_name]
A38: TC_CO_05 | B38: Thanh toán | C38: Negative | D38: Bỏ trống Postal Code | E38: Đang ở bước "Checkout: Your Information" | F38: 1. Nhập First Name, Last Name 2. Để trống Postal Code 3. Bấm Continue | G38: Thuy / Ta / (trống) | H38: Hiển thị lỗi "Error: Postal Code is required" | I38: High | J38: Đã có | L38: Not run | N38: test_checkout_requires_postal_code
A39: TC_CO_06 | B39: Thanh toán | C39: Negative | D39: Bỏ trống cả 3 ô | E39: Đang ở bước "Checkout: Your Information" | F39: 1. Để trống cả 3 ô 2. Bấm Continue | G39: (trống) | H39: Hiển thị lỗi của ô đầu tiên: "Error: First Name is required" | I39: Medium | J39: Đã có | L39: Not run | N39: test_checkout_required_fields[all_empty]
A40: TC_CO_07 | B40: Thanh toán | C40: Negative | D40: First Name chỉ nhập dấu cách | E40: Đang ở bước "Checkout: Your Information" | F40: 1. Nhập First Name là dấu cách 2. Nhập Last Name, Postal Code 3. Bấm Continue | G40: " " / Ta / 100000 | H40: Báo lỗi First Name là bắt buộc | I40: Low | J40: Test tay | L40: Not run | M40: Cần chạy tay để xác nhận hành vi thực tế. Nếu vẫn qua được bước sau → có thể log bug
...
